Workbook

Sheet Rekap Inv
A1: ="Biaya "&DAY($I$1)&" - "&TEXT(EOMONTH($I$1,0),"[$-id-ID]d mmmm yyyy;@") -> Biaya 1 - 31 Januari 2026 | H1: Tanggal awal tagihan | I1: 46023
H2: HSPHK | I2: 1500000
H3: Standby rate / day | I3: 0.25
A4: Total invoice | D4: IDR
A5: ="Untuk 1 unit "&'7116'!$D$3 -> Untuk 1 unit {{unit_sn}} | D5: ='7116'!S37 -> #VALUE!
A6: Total | D6: =SUM(D5:E5) -> #VALUE!
A9: Pihak kesatu | E9: Pihak Kedua
A15: Adam S Nasution | E15: Benny
A16: Field Manager Adera Field | E16: Direktur Utama

Sheet 4060 2
A1: DATE | B1: SUCTION PRESSURE | C1: DISCHARGE PRESSURE | D1: FLOWRATE | E1: RUNNING TIME | F1: PERFORMANCE | G1: CORRECTED w/ RUNNING TIME CURVE FLOWRATE | H1: CURVE FLOWRATE (24 hrs OL/) | Q1: SUCTION PRESSURE (psig) | R1: DISCHARGE PRESSURE (psig) | S1: VALVE CONFIGURATION | T1: FLOWRATE (MSCFD)
B2: psig | C2: psig | D2: MSCFD | F2: % | G2: MSCFD | H2: MSCFD | K2: 1 | Q2: -9 | R2: 50 | S2: M-4-0 | T2: 19.2
A3: 1 | B3: -0.2 | C3: 59.8 | D3: 80.9 | E3: 1 | F3: =IF(AND(D3="",G3=""),"",D3/G3) -> 0.72183677 | G3: =IF(AND(E3="",H3=""),"",IF(D3<1,H3*E3/1000,H3*E3)) -> 112.0752 | H3: =IF(OR(B3="",C3=""),"",M4) -> 112.0752 | K3: SP | L3: DP | M3: FLOWRATE | Q3: -8 | R3: 50 | S3: M-4-0 | T3: 30
A4: 2 | B4: 0 | C4: 60.5 | D4: 99 | E4: 1 | F4: =IF(AND(D4="",G4=""),"",D4/G4) -> 0.86878686 | G4: =IF(AND(E4="",H4=""),"",IF(D4<1,H4*E4/1000,H4*E4)) -> 113.952 | H4: =IF(OR(B4="",C4=""),"",M14) -> 113.952 | K4: =B3 -> -0.2 | L4: =C3 -> 59.8 | M4: =IF(OR(K4="",L4=""),"",IF(N8<>"",N8,IF(OR(M8<>"",N7<>"",O8<>"",N9<>""),MIN(M8,N7,O8,N9),MIN(M7:O9)))) -> 112.0752 | Q4: -7 | R4: 50 | S4: M-4-0 | T4: 41.4
A5: 3 | B5: -0.1 | C5: 60.6 | D5: 96.5 | E5: 1 | F5: =IF(AND(D5="",G5=""),"",D5/G5) -> 0.85584243 | G5: =IF(AND(E5="",H5=""),"",IF(D5<1,H5*E5/1000,H5*E5)) -> 112.7544 | H5: =IF(OR(B5="",C5=""),"",M24) -> 112.7544 | N5: Discharge Lapangan : | Q5: -6 | R5: 50 | S5: M-4-0 | T5: 52.2
A6: 4 | B6: 0 | C6: 61.7 | D6: 102.3 | E6: 1 | F6: =IF(AND(D6="",G6=""),"",D6/G6) -> 0.90322512 | G6: =IF(AND(E6="",H6=""),"",IF(D6<1,H6*E6/1000,H6*E6)) -> 113.2608 | H6: =IF(OR(B6="",C6=""),"",M37) -> 113.2608 | M6: =IF(N6>=350,350,IF(N6>=325,325,IF(N6>=300,300,IF(N6>=275,275,IF(N6>=250,250,IF(N6>=225,225,IF(N6>=200,200,IF(N6>=175,175,IF(N6>=150,150,IF(N6>=125,125,IF(N6>=100,100,IF(N6>=75,75,50)))))))))))) -> 50 | N6: =L4 -> 59.8 | O6: =IF(N6<=50,50,IF(N6<=75,75,IF(N6<=100,100,IF(N6<=125,125,IF(N6<=150,150,IF(N6<=175,175,IF(N6<=200,200,IF(N6<=225,225,IF(N6<=250,250,IF(N6<=275,275,IF(N6<=300,300,IF(N6<=325,325,350)))))))))))) -> 75 | Q6: -5 | R6: 50 | S6: M-4-0 | T6: 63.6
A7: 5 | B7: 0 | C7: 61 | D7: 95.1 | E7: 1 | F7: =IF(AND(D7="",G7=""),"",D7/G7) -> 0.83667652 | G7: =IF(AND(E7="",H7=""),"",IF(D7<1,H7*E7/1000,H7*E7)) -> 113.664 | H7: =IF(OR(B7="",C7=""),"",M47) -> 113.664 | L7: =IF(L8>=0,ROUNDDOWN(L8,0),ROUNDUP(L8,0)) -> -1 | M7: =IF(M6=350,VLOOKUP($L7,$Q$454:$T$478,4),IF(M6=325,VLOOKUP(L7,$Q$426:$T$453,4),IF(M6=300,VLOOKUP(L7,$Q$395:$T$425,4),IF(M6=275,VLOOKUP(L7,$Q$362:$T$394,4),IF(M6=250,VLOOKUP(L7,$Q$329:$T$361,4),IF(M6=225,VLOOKUP(L7,$Q$294:$T$328,4),IF(M6=200,VLOOKUP(L7,$Q$258:$T$293,4),IF(M6=175,VLOOKUP(L7,$Q$224:$T$257,4),IF(M6=150,VLOOKUP(L7,$Q$179:$T$222,4),IF(M6=125,VLOOKUP(L7,$Q$128:$T$177,4),IF(M6=100,VLOOKUP(L7,$Q$83:$T$126,4),IF(M6=75,VLOOKUP(L7,$Q$41:$T$81,4),IF(M6=50,VLOOKUP(L7,$Q$2:$T$39,4)))))))))))))) -> 108.6 | N7: =IFERROR((N6-M6)/(O6-M6)*(O7-M7)+M7,"") -> 102.9552 | O7: =IF(O$6=350,VLOOKUP($L7,$Q$454:$T$478,4),IF(O$6=325,VLOOKUP($L7,$Q$426:$T$453,4),IF(O$6=300,VLOOKUP($L7,$Q$395:$T$425,4),IF(O$6=275,VLOOKUP($L7,$Q$362:$T$394,4),IF(O$6=250,VLOOKUP($L7,$Q$329:$T$361,4),IF(O$6=225,VLOOKUP($L7,$Q$294:$T$328,4),IF(O$6=200,VLOOKUP($L7,$Q$258:$T$293,4),IF(O$6=175,VLOOKUP($L7,$Q$224:$T$257,4),IF(O$6=150,VLOOKUP($L7,$Q$179:$T$222,4),IF(O$6=125,VLOOKUP($L7,$Q$128:$T$177,4),IF(O$6=100,VLOOKUP($L7,$Q$83:$T$126,4),IF(O$6=75,VLOOKUP($L7,$Q$41:$T$81,4),IF(O$6=50,VLOOKUP($L7,$Q$2:$T$39,4)))))))))))))) -> 94.2 | Q7: -4 | R7: 50 | S7: M-4-0 | T7: 74.4
A8: 6 | B8: 0.1 | C8: 60.4 | D8: 102 | E8: 1 | F8: =IF(AND(D8="",G8=""),"",D8/G8) -> 0.88672829 | G8: =IF(AND(E8="",H8=""),"",IF(D8<1,H8*E8/1000,H8*E8)) -> 115.0296 | H8: =IF(OR(B8="",C8=""),"",M57) -> 115.0296 | K8: Suction Lapangan : | L8: =K4 -> -0.2 | M8: =IFERROR((L8-L7)/(L9-L7)*(M9-M7)+M7,"") -> 117.72 | N8: =IFERROR((N6-O6)/(M6-O6)*(M8-O8)+O8,"") -> 112.0752 | O8: =IFERROR((L8-L7)/(L9-L7)*(O9-O7)+O7,"") -> 103.32 | Q8: -3 | R8: 50 | S8: M-4-0 | T8: 85.8
A9: 7 | B9: 0 | C9: 60.4 | D9: 97 | E9: 1 | F9: =IF(AND(D9="",G9=""),"",D9/G9) -> 0.85080555 | G9: =IF(AND(E9="",H9=""),"",IF(D9<1,H9*E9/1000,H9*E9)) -> 114.0096 | H9: =IF(OR(B9="",C9=""),"",M67) -> 114.0096 | L9: =IF(L8>=0,ROUNDUP(L8,0),ROUNDDOWN(L8,0)) -> 0 | M9: =IF(M6=350,VLOOKUP($L9,$Q$454:$T$478,4),IF(M6=325,VLOOKUP(L9,$Q$426:$T$453,4),IF(M6=300,VLOOKUP(L9,$Q$395:$T$425,4),IF(M6=275,VLOOKUP(L9,$Q$362:$T$394,4),IF(M6=250,VLOOKUP(L9,$Q$329:$T$361,4),IF(M6=225,VLOOKUP(L9,$Q$294:$T$328,4),IF(M6=200,VLOOKUP(L9,$Q$258:$T$293,4),IF(M6=175,VLOOKUP(L9,$Q$224:$T$257,4),IF(M6=150,VLOOKUP(L9,$Q$179:$T$222,4),IF(M6=125,VLOOKUP(L9,$Q$128:$T$177,4),IF(M6=100,VLOOKUP(L9,$Q$83:$T$126,4),IF(M6=75,VLOOKUP(L9,$Q$41:$T$81,4),IF(M6=50,VLOOKUP(L9,$Q$2:$T$39,4)))))))))))))) -> 120 | N9: =IFERROR((N6-M6)/(O6-M6)*(O9-M9)+M9,"") -> 114.3552 | O9: =IF(O$6=350,VLOOKUP($L9,$Q$454:$T$478,4),IF(O$6=325,VLOOKUP($L9,$Q$426:$T$453,4),IF(O$6=300,VLOOKUP($L9,$Q$395:$T$425,4),IF(O$6=275,VLOOKUP($L9,$Q$362:$T$394,4),IF(O$6=250,VLOOKUP($L9,$Q$329:$T$361,4),IF(O$6=225,VLOOKUP($L9,$Q$294:$T$328,4),IF(O$6=200,VLOOKUP($L9,$Q$258:$T$293,4),IF(O$6=175,VLOOKUP($L9,$Q$224:$T$257,4),IF(O$6=150,VLOOKUP($L9,$Q$179:$T$222,4),IF(O$6=125,VLOOKUP($L9,$Q$128:$T$177,4),IF(O$6=100,VLOOKUP($L9,$Q$83:$T$126,4),IF(O$6=75,VLOOKUP($L9,$Q$41:$T$81,4),IF(O$6=50,VLOOKUP($L9,$Q$2:$T$39,4)))))))))))))) -> 105.6 | Q9: -2 | R9: 50 | S9: M-4-0 | T9: 97.2
A10: 8 | B10: 0.3 | C10: 61.2 | D10: 88.6 | E10: 1 | F10: =IF(AND(D10="",G10=""),"",D10/G10) -> 0.75980543 | G10: =IF(AND(E10="",H10=""),"",IF(D10<1,H10*E10/1000,H10*E10)) -> 116.6088 | H10: =IF(OR(B10="",C10=""),"",M77) -> 116.6088 | Q10: -1 | R10: 50 | S10: M-4-0 | T10: 108.6
A11: 9 | B11: 0.1 | C11: 61.2 | D11: 102.3 | E11: 1 | F11: =IF(AND(D11="",G11=""),"",D11/G11) -> 0.89291325 | G11: =IF(AND(E11="",H11=""),"",IF(D11<1,H11*E11/1000,H11*E11)) -> 114.5688 | H11: =IF(OR(B11="",C11=""),"",M87) -> 114.5688 | Q11: 0 | R11: 50 | S11: M-4-0 | T11: 120
A12: 10 | B12: 0.2 | C12: 61 | D12: 99 | E12: 1 | F12: =IF(AND(D12="",G12=""),"",D12/G12) -> 0.85563161 | G12: =IF(AND(E12="",H12=""),"",IF(D12<1,H12*E12/1000,H12*E12)) -> 115.704 | H12: =IF(OR(B12="",C12=""),"",M97) -> 115.704 | K12: 2 | Q12: 1 | R12: 50 | S12: M-4-0 | T12: 130.2
A13: 11 | B13: -0.3 | C13: 59.8 | D13: 104.4 | E13: 1 | F13: =IF(AND(D13="",G13=""),"",D13/G13) -> 0.94108993 | G13: =IF(AND(E13="",H13=""),"",IF(D13<1,H13*E13/1000,H13*E13)) -> 110.9352 | H13: =IF(OR(B13="",C13=""),"",M107) -> 110.9352 | K13: SP | L13: DP | M13: FLOWRATE | Q13: 2 | R13: 50 | S13: M-4-0 | T13: 140.4
A14: 12 | B14: 0 | C14: 61.7 | D14: 95.3 | E14: 1 | F14: =IF(AND(D14="",G14=""),"",D14/G14) -> 0.84142086 | G14: =IF(AND(E14="",H14=""),"",IF(D14<1,H14*E14/1000,H14*E14)) -> 113.2608 | H14: =IF(OR(B14="",C14=""),"",M117) -> 113.2608 | K14: =B4 -> 0 | L14: =C4 -> 60.5 | M14: =IF(OR(K14="",L14=""),"",IF(N18<>"",N18,IF(OR(M18<>"",N17<>"",O18<>"",N19<>""),MIN(M18,N17,O18,N19),MIN(M17:O19)))) -> 113.952 | Q14: 3 | R14: 50 | S14: M-4-0 | T14: 150.6
A15: 13 | B15: 0.2 | C15: 58.8 | D15: 95.3 | E15: 1 | F15: =IF(AND(D15="",G15=""),"",D15/G15) -> 0.81473046 | G15: =IF(AND(E15="",H15=""),"",IF(D15<1,H15*E15/1000,H15*E15)) -> 116.9712 | H15: =IF(OR(B15="",C15=""),"",M127) -> 116.9712 | N15: Discharge Lapangan : | Q15: 4 | R15: 50 | S15: M-4-0 | T15: 161.4
A16: 14 | B16: 0.2 | C16: 60.6 | D16: 106.6 | E16: 1 | F16: =IF(AND(D16="",G16=""),"",D16/G16) -> 0.9194855 | G16: =IF(AND(E16="",H16=""),"",IF(D16<1,H16*E16/1000,H16*E16)) -> 115.9344 | H16: =IF(OR(B16="",C16=""),"",M137) -> 115.9344 | M16: =IF(N16>=350,350,IF(N16>=325,325,IF(N16>=300,300,IF(N16>=275,275,IF(N16>=250,250,IF(N16>=225,225,IF(N16>=200,200,IF(N16>=175,175,IF(N16>=150,150,IF(N16>=125,125,IF(N16>=100,100,IF(N16>=75,75,50)))))))))))) -> 50 | N16: =L14 -> 60.5 | O16: =IF(N16<=50,50,IF(N16<=75,75,IF(N16<=100,100,IF(N16<=125,125,IF(N16<=150,150,IF(N16<=175,175,IF(N16<=200,200,IF(N16<=225,225,IF(N16<=250,250,IF(N16<=275,275,IF(N16<=300,300,IF(N16<=325,325,350)))))))))))) -> 75 | Q16: 5 | R16: 50 | S16: M-4-0 | T16: 171.6
A17: 15 | B17: 0.6 | C17: 62.8 | D17: 117.1 | E17: 1 | F17: =IF(AND(D17="",G17=""),"",D17/G17) -> 0.98612852 | G17: =IF(AND(E17="",H17=""),"",IF(D17<1,H17*E17/1000,H17*E17)) -> 118.7472 | H17: =IF(OR(B17="",C17=""),"",M147) -> 118.7472 | L17: =IF(L18>=0,ROUNDDOWN(L18,0),ROUNDUP(L18,0)) -> 0 | M17: =IF(M16=350,VLOOKUP($L17,$Q$454:$T$478,4),IF(M16=325,VLOOKUP(L17,$Q$426:$T$453,4),IF(M16=300,VLOOKUP(L17,$Q$395:$T$425,4),IF(M16=275,VLOOKUP(L17,$Q$362:$T$394,4),IF(M16=250,VLOOKUP(L17,$Q$329:$T$361,4),IF(M16=225,VLOOKUP(L17,$Q$294:$T$328,4),IF(M16=200,VLOOKUP(L17,$Q$258:$T$293,4),IF(M16=175,VLOOKUP(L17,$Q$224:$T$257,4),IF(M16=150,VLOOKUP(L17,$Q$179:$T$222,4),IF(M16=125,VLOOKUP(L17,$Q$128:$T$177,4),IF(M16=100,VLOOKUP(L17,$Q$83:$T$126,4),IF(M16=75,VLOOKUP(L17,$Q$41:$T$81,4),IF(M16=50,VLOOKUP(L17,$Q$2:$T$39,4)))))))))))))) -> 120 | N17: =IFERROR((N16-M16)/(O16-M16)*(O17-M17)+M17,"") -> 113.952 | O17: =IF(O16=350,VLOOKUP($L17,$Q$454:$T$478,4),IF(O16=325,VLOOKUP($L17,$Q$426:$T$453,4),IF(O16=300,VLOOKUP($L17,$Q$395:$T$425,4),IF(O16=275,VLOOKUP($L17,$Q$362:$T$394,4),IF(O16=250,VLOOKUP($L17,$Q$329:$T$361,4),IF(O16=225,VLOOKUP($L17,$Q$294:$T$328,4),IF(O16=200,VLOOKUP($L17,$Q$258:$T$293,4),IF(O16=175,VLOOKUP($L17,$Q$224:$T$257,4),IF(O16=150,VLOOKUP($L17,$Q$179:$T$222,4),IF(O16=125,VLOOKUP($L17,$Q$128:$T$177,4),IF(O16=100,VLOOKUP($L17,$Q$83:$T$126,4),IF(O16=75,VLOOKUP($L17,$Q$41:$T$81,4),IF(O16=50,VLOOKUP($L17,$Q$2:$T$39,4)))))))))))))) -> 105.6 | Q17: 6 | R17: 50 | S17: M-4-0 | T17: 181.8
A18: 16 | B18: 0.9 | C18: 63.9 | D18: 117.6 | E18: 1 | F18: =IF(AND(D18="",G18=""),"",D18/G18) -> 0.97050843 | G18: =IF(AND(E18="",H18=""),"",IF(D18<1,H18*E18/1000,H18*E18)) -> 121.1736 | H18: =IF(OR(B18="",C18=""),"",M157) -> 121.1736 | K18: Suction Lapangan : | L18: =K14 -> 0 | M18: =IFERROR((L18-L17)/(L19-L17)*(M19-M17)+M17,"") | N18: =IFERROR((N16-O16)/(M16-O16)*(M18-O18)+O18,"") | O18: =IFERROR((L18-L17)/(L19-L17)*(O19-O17)+O17,"") | Q18: 7 | R18: 50 | S18: M-4-0 | T18: 192
A19: 17 | B19: 1.4 | C19: 63.5 | D19: 130.3 | E19: 1 | F19: =IF(AND(D19="",G19=""),"",D19/G19) -> 1.030007 | G19: =IF(AND(E19="",H19=""),"",IF(D19<1,H19*E19/1000,H19*E19)) -> 126.504 | H19: =IF(OR(B19="",C19=""),"",M167) -> 126.504 | L19: =IF(L18>=0,ROUNDUP(L18,0),ROUNDDOWN(L18,0)) -> 0 | M19: =IF(M16=350,VLOOKUP($L19,$Q$454:$T$478,4),IF(M16=325,VLOOKUP(L19,$Q$426:$T$453,4),IF(M16=300,VLOOKUP(L19,$Q$395:$T$425,4),IF(M16=275,VLOOKUP(L19,$Q$362:$T$394,4),IF(M16=250,VLOOKUP(L19,$Q$329:$T$361,4),IF(M16=225,VLOOKUP(L19,$Q$294:$T$328,4),IF(M16=200,VLOOKUP(L19,$Q$258:$T$293,4),IF(M16=175,VLOOKUP(L19,$Q$224:$T$257,4),IF(M16=150,VLOOKUP(L19,$Q$179:$T$222,4),IF(M16=125,VLOOKUP(L19,$Q$128:$T$177,4),IF(M16=100,VLOOKUP(L19,$Q$83:$T$126,4),IF(M16=75,VLOOKUP(L19,$Q$41:$T$81,4),IF(M16=50,VLOOKUP(L19,$Q$2:$T$39,4)))))))))))))) -> 120 | N19: =IFERROR((N16-M16)/(O16-M16)*(O19-M19)+M19,"") -> 113.952 | O19: =IF(O16=350,VLOOKUP($L19,$Q$454:$T$478,4),IF(O16=325,VLOOKUP($L19,$Q$426:$T$453,4),IF(O16=300,VLOOKUP($L19,$Q$395:$T$425,4),IF(O16=275,VLOOKUP($L19,$Q$362:$T$394,4),IF(O16=250,VLOOKUP($L19,$Q$329:$T$361,4),IF(O16=225,VLOOKUP($L19,$Q$294:$T$328,4),IF(O16=200,VLOOKUP($L19,$Q$258:$T$293,4),IF(O16=175,VLOOKUP($L19,$Q$224:$T$257,4),IF(O16=150,VLOOKUP($L19,$Q$179:$T$222,4),IF(O16=125,VLOOKUP($L19,$Q$128:$T$177,4),IF(O16=100,VLOOKUP($L19,$Q$83:$T$126,4),IF(O16=75,VLOOKUP($L19,$Q$41:$T$81,4),IF(O16=50,VLOOKUP($L19,$Q$2:$T$39,4)))))))))))))) -> 105.6 | Q19: 8 | R19: 50 | S19: M-4-0 | T19: 202.8
A20: 18 | B20: 1.5 | C20: 63 | D20: 125.5 | E20: 1 | F20: =IF(AND(D20="",G20=""),"",D20/G20) -> 0.98191093 | G20: =IF(AND(E20="",H20=""),"",IF(D20<1,H20*E20/1000,H20*E20)) -> 127.812 | H20: =IF(OR(B20="",C20=""),"",M177) -> 127.812 | Q20: 9 | R20: 50 | S20: M-4-0 | T20: 213
A21: 19 | B21: 1.5 | C21: 63.3 | D21: 119.7 | E21: 1 | F21: =IF(AND(D21="",G21=""),"",D21/G21) -> 0.93779967 | G21: =IF(AND(E21="",H21=""),"",IF(D21<1,H21*E21/1000,H21*E21)) -> 127.6392 | H21: =IF(OR(B21="",C21=""),"",M187) -> 127.6392 | Q21: 10 | R21: 50 | S21: M-4-0 | T21: 223.8
A22: 20 | B22: 1.7 | C22: 62.9 | D22: 122.8 | E22: 1 | F22: =IF(AND(D22="",G22=""),"",D22/G22) -> 0.94527271 | G22: =IF(AND(E22="",H22=""),"",IF(D22<1,H22*E22/1000,H22*E22)) -> 129.9096 | H22: =IF(OR(B22="",C22=""),"",M197) -> 129.9096 | K22: 3 | Q22: 11 | R22: 50 | S22: M-4-0 | T22: 234
A23: 21 | B23: 1.8 | C23: 63.2 | D23: 127.8 | E23: 1 | F23: =IF(AND(D23="",G23=""),"",D23/G23) -> 0.97738703 | G23: =IF(AND(E23="",H23=""),"",IF(D23<1,H23*E23/1000,H23*E23)) -> 130.7568 | H23: =IF(OR(B23="",C23=""),"",M207) -> 130.7568 | K23: SP | L23: DP | M23: FLOWRATE | Q23: 12 | R23: 50 | S23: M-4-0 | T23: 244.2
A24: 22 | B24: 2.2 | C24: 63.8 | D24: 135.5 | E24: 1 | F24: =IF(AND(D24="",G24=""),"",D24/G24) -> 1.0075009 | G24: =IF(AND(E24="",H24=""),"",IF(D24<1,H24*E24/1000,H24*E24)) -> 134.4912 | H24: =IF(OR(B24="",C24=""),"",M217) -> 134.4912 | K24: =B5 -> -0.1 | L24: =C5 -> 60.6 | M24: =IF(OR(K24="",L24=""),"",IF(N28<>"",N28,IF(OR(M28<>"",N27<>"",O28<>"",N29<>""),MIN(M28,N27,O28,N29),MIN(M27:O29)))) -> 112.7544 | Q24: 13 | R24: 50 | S24: M-4-0 | T24: 255
A25: 23 | B25: 1.5 | C25: 62.9 | D25: 124.3 | E25: 1 | F25: =IF(AND(D25="",G25=""),"",D25/G25) -> 0.97208406 | G25: =IF(AND(E25="",H25=""),"",IF(D25<1,H25*E25/1000,H25*E25)) -> 127.8696 | H25: =IF(OR(B25="",C25=""),"",M227) -> 127.8696 | N25: Discharge Lapangan : | Q25: 14 | R25: 50 | S25: M-4-0 | T25: 265.2
A26: 24 | B26: 2.4 | C26: 64.1 | D26: 138.9 | E26: 1 | F26: =IF(AND(D26="",G26=""),"",D26/G26) -> 1.0186391 | G26: =IF(AND(E26="",H26=""),"",IF(D26<1,H26*E26/1000,H26*E26)) -> 136.3584 | H26: =IF(OR(B26="",C26=""),"",M237) -> 136.3584 | M26: =IF(N26>=350,350,IF(N26>=325,325,IF(N26>=300,300,IF(N26>=275,275,IF(N26>=250,250,IF(N26>=225,225,IF(N26>=200,200,IF(N26>=175,175,IF(N26>=150,150,IF(N26>=125,125,IF(N26>=100,100,IF(N26>=75,75,50)))))))))))) -> 50 | N26: =L24 -> 60.6 | O26: =IF(N26<=50,50,IF(N26<=75,75,IF(N26<=100,100,IF(N26<=125,125,IF(N26<=150,150,IF(N26<=175,175,IF(N26<=200,200,IF(N26<=225,225,IF(N26<=250,250,IF(N26<=275,275,IF(N26<=300,300,IF(N26<=325,325,350)))))))))))) -> 75 | Q26: 15 | R26: 50 | S26: M-4-0 | T26: 276
A27: 25 | B27: 2 | C27: 63.4 | D27: 130.3 | E27: 1 | F27: =IF(AND(D27="",G27=""),"",D27/G27) -> 0.98205026 | G27: =IF(AND(E27="",H27=""),"",IF(D27<1,H27*E27/1000,H27*E27)) -> 132.6816 | H27: =IF(OR(B27="",C27=""),"",M247) -> 132.6816 | L27: =IF(L28>=0,ROUNDDOWN(L28,0),ROUNDUP(L28,0)) -> -1 | M27: =IF(M26=350,VLOOKUP($L27,$Q$454:$T$478,4),IF(M26=325,VLOOKUP(L27,$Q$426:$T$453,4),IF(M26=300,VLOOKUP(L27,$Q$395:$T$425,4),IF(M26=275,VLOOKUP(L27,$Q$362:$T$394,4),IF(M26=250,VLOOKUP(L27,$Q$329:$T$361,4),IF(M26=225,VLOOKUP(L27,$Q$294:$T$328,4),IF(M26=200,VLOOKUP(L27,$Q$258:$T$293,4),IF(M26=175,VLOOKUP(L27,$Q$224:$T$257,4),IF(M26=150,VLOOKUP(L27,$Q$179:$T$222,4),IF(M26=125,VLOOKUP(L27,$Q$128:$T$177,4),IF(M26=100,VLOOKUP(L27,$Q$83:$T$126,4),IF(M26=75,VLOOKUP(L27,$Q$41:$T$81,4),IF(M26=50,VLOOKUP(L27,$Q$2:$T$39,4)))))))))))))) -> 108.6 | N27: =IFERROR((N26-M26)/(O26-M26)*(O27-M27)+M27,"") -> 102.4944 | O27: =IF(O26=350,VLOOKUP($L27,$Q$454:$T$478,4),IF(O26=325,VLOOKUP($L27,$Q$426:$T$453,4),IF(O26=300,VLOOKUP($L27,$Q$395:$T$425,4),IF(O26=275,VLOOKUP($L27,$Q$362:$T$394,4),IF(O26=250,VLOOKUP($L27,$Q$329:$T$361,4),IF(O26=225,VLOOKUP($L27,$Q$294:$T$328,4),IF(O26=200,VLOOKUP($L27,$Q$258:$T$293,4),IF(O26=175,VLOOKUP($L27,$Q$224:$T$257,4),IF(O26=150,VLOOKUP($L27,$Q$179:$T$222,4),IF(O26=125,VLOOKUP($L27,$Q$128:$T$177,4),IF(O26=100,VLOOKUP($L27,$Q$83:$T$126,4),IF(O26=75,VLOOKUP($L27,$Q$41:$T$81,4),IF(O26=50,VLOOKUP($L27,$Q$2:$T$39,4)))))))))))))) -> 94.2 | Q27: 16 | R27: 50 | S27: M-4-0 | T27: 286.2
A28: 26 | B28: 2 | C28: 62.6 | D28: 119.7 | E28: 1 | F28: =IF(AND(D28="",G28=""),"",D28/G28) -> 0.89903742 | G28: =IF(AND(E28="",H28=""),"",IF(D28<1,H28*E28/1000,H28*E28)) -> 133.1424 | H28: =IF(OR(B28="",C28=""),"",M257) -> 133.1424 | K28: Suction Lapangan : | L28: =K24 -> -0.1 | M28: =IFERROR((L28-L27)/(L29-L27)*(M29-M27)+M27,"") -> 118.86 | N28: =IFERROR((N26-O26)/(M26-O26)*(M28-O28)+O28,"") -> 112.7544 | O28: =IFERROR((L28-L27)/(L29-L27)*(O29-O27)+O27,"") -> 104.46 | Q28: 17 | R28: 50 | S28: M-4-0 | T28: 297
A29: 27 | B29: 2.2 | C29: 63.1 | D29: 129.9 | E29: 1 | F29: =IF(AND(D29="",G29=""),"",D29/G29) -> 0.96297548 | G29: =IF(AND(E29="",H29=""),"",IF(D29<1,H29*E29/1000,H29*E29)) -> 134.8944 | H29: =IF(OR(B29="",C29=""),"",M267) -> 134.8944 | L29: =IF(L28>=0,ROUNDUP(L28,0),ROUNDDOWN(L28,0)) -> 0 | M29: =IF(M26=350,VLOOKUP($L29,$Q$454:$T$478,4),IF(M26=325,VLOOKUP(L29,$Q$426:$T$453,4),IF(M26=300,VLOOKUP(L29,$Q$395:$T$425,4),IF(M26=275,VLOOKUP(L29,$Q$362:$T$394,4),IF(M26=250,VLOOKUP(L29,$Q$329:$T$361,4),IF(M26=225,VLOOKUP(L29,$Q$294:$T$328,4),IF(M26=200,VLOOKUP(L29,$Q$258:$T$293,4),IF(M26=175,VLOOKUP(L29,$Q$224:$T$257,4),IF(M26=150,VLOOKUP(L29,$Q$179:$T$222,4),IF(M26=125,VLOOKUP(L29,$Q$128:$T$177,4),IF(M26=100,VLOOKUP(L29,$Q$83:$T$126,4),IF(M26=75,VLOOKUP(L29,$Q$41:$T$81,4),IF(M26=50,VLOOKUP(L29,$Q$2:$T$39,4)))))))))))))) -> 120 | N29: =IFERROR((N26-M26)/(O26-M26)*(O29-M29)+M29,"") -> 113.8944 | O29: =IF(O26=350,VLOOKUP($L29,$Q$454:$T$478,4),IF(O26=325,VLOOKUP($L29,$Q$426:$T$453,4),IF(O26=300,VLOOKUP($L29,$Q$395:$T$425,4),IF(O26=275,VLOOKUP($L29,$Q$362:$T$394,4),IF(O26=250,VLOOKUP($L29,$Q$329:$T$361,4),IF(O26=225,VLOOKUP($L29,$Q$294:$T$328,4),IF(O26=200,VLOOKUP($L29,$Q$258:$T$293,4),IF(O26=175,VLOOKUP($L29,$Q$224:$T$257,4),IF(O26=150,VLOOKUP($L29,$Q$179:$T$222,4),IF(O26=125,VLOOKUP($L29,$Q$128:$T$177,4),IF(O26=100,VLOOKUP($L29,$Q$83:$T$126,4),IF(O26=75,VLOOKUP($L29,$Q$41:$T$81,4),IF(O26=50,VLOOKUP($L29,$Q$2:$T$39,4)))))))))))))) -> 105.6 | Q29: 18 | R29: 50 | S29: M-4-0 | T29: 307.8
A30: 28 | B30: 2.3 | C30: 64.1 | D30: 143 | E30: 1 | F30: =IF(AND(D30="",G30=""),"",D30/G30) -> 1.0566107 | G30: =IF(AND(E30="",H30=""),"",IF(D30<1,H30*E30/1000,H30*E30)) -> 135.3384 | H30: =IF(OR(B30="",C30=""),"",M277) -> 135.3384 | Q30: 19 | R30: 50 | S30: M-4-0 | T30: 318
A31: 29 | B31: 2.8 | C31: 65 | D31: 137.9 | E31: 0.95833333 | F31: =IF(AND(D31="",G31=""),"",D31/G31) -> 1.0284138 | G31: =IF(AND(E31="",H31=""),"",IF(D31<1,H31*E31/1000,H31*E31)) -> 134.09 | H31: =IF(OR(B31="",C31=""),"",M287) -> 139.92 | Q31: 20 | R31: 50 | S31: M-4-0 | T31: 328.8
A32: 30 | B32: 1.4 | C32: 61.1 | D32: 103.3 | E32: 1 | F32: =IF(AND(D32="",G32=""),"",D32/G32) -> 0.80774813 | G32: =IF(AND(E32="",H32=""),"",IF(D32<1,H32*E32/1000,H32*E32)) -> 127.8864 | H32: =IF(OR(B32="",C32=""),"",M297) -> 127.8864 | K32: 4 | Q32: 21 | R32: 50 | S32: M-4-0 | T32: 339
A33: 31 | B33: 1.3 | C33: 61.8 | D33: 89.9 | E33: 1 | F33: =IF(AND(D33="",G33=""),"",D33/G33) -> 0.71087874 | G33: =IF(AND(E33="",H33=""),"",IF(D33<1,H33*E33/1000,H33*E33)) -> 126.4632 | H33: =IF(OR(B33="",C33=""),"",M307) -> 126.4632 | K33: SP | L33: DP | M33: FLOWRATE | Q33: 22 | R33: 50 | S33: M-4-0 | T33: 349.8
A34: AVERAGE | B34: =IFERROR(AVERAGE(B3:B33),"") -> 0.96774194 | C34: =IFERROR(AVERAGE(C3:C33),"") -> 62.03871 | D34: =IFERROR(AVERAGE(D3:D33),"") -> 112.1871 | E34: =IFERROR(AVERAGE(E3:E33),"") -> 0.99865591 | F34: =IFERROR(AVERAGE(F3:F33),"") -> 0.9104494 | K34: =IF(B6="","",B6) -> 0 | L34: =IF(C6="","",C6) -> 61.7 | M34: =IF(OR(K34="",L34=""),"",AVERAGEIF(M40:O40,"<>0",M40:O40)) -> 112.9536 | Q34: 23 | R34: 50 | S34: M-4-0 | T34: 600
A35: MIN | B35: =IF(COUNT(B3:B33)>0,MIN(B3:B33),"") -> -0.3 | C35: =IF(COUNT(C3:C33)>0,MIN(C3:C33),"") -> 58.8 | D35: =IF(COUNT(D3:D33)>0,MIN(D3:D33),"") -> 80.9 | E35: =IF(COUNT(E3:E33)>0,MIN(E3:E33),"") -> 0.95833333 | F35: =IF(COUNT(F3:F33)>0,MIN(F3:F33),"") -> 0.71087874 | N35: Discharge Lapangan : | Q35: 24 | R35: 50 | S35: M-4-0 | T35: 618
A36: MAX | B36: =IF(COUNT(B3:B33)>0,MAX(B3:B33),"") -> 2.8 | C36: =IF(COUNT(C3:C33)>0,MAX(C3:C33),"") -> 65 | D36: =IF(COUNT(D3:D33)>0,MAX(D3:D33),"") -> 143 | E36: =IF(COUNT(E3:E33)>0,MAX(E3:E33),"") -> 1 | F36: =IF(COUNT(F3:F33)>0,MAX(F3:F33),"") -> 1.0566107 | M36: =IF(N36>=350,350,IF(N36>=325,325,IF(N36>=300,300,IF(N36>=275,275,IF(N36>=250,250,IF(N36>=225,225,IF(N36>=200,200,IF(N36>=175,175,IF(N36>=150,150,IF(N36>=125,125,IF(N36>=100,100,IF(N36>=75,75,50)))))))))))) -> 50 | N36: =L34 -> 61.7 | O36: =IF(N36<=50,50,IF(N36<=75,75,IF(N36<=100,100,IF(N36<=125,125,IF(N36<=150,150,IF(N36<=175,175,IF(N36<=200,200,IF(N36<=225,225,IF(N36<=250,250,IF(N36<=275,275,IF(N36<=300,300,IF(N36<=325,325,350)))))))))))) -> 75 | Q36: 25 | R36: 50 | S36: M-4-0 | T36: 636
K37: =B6 -> 0 | L37: =C6 -> 61.7 | M37: =IF(OR(K37="",L37=""),"",IF(N41<>"",N41,IF(OR(M41<>"",N40<>"",O41<>"",N42<>""),MIN(M41,N40,O41,N42),MIN(M40:O42)))) -> 113.2608 | Q37: 23 | R37: 50 | S37: M-4-0 | T37: 360
N38: Discharge Lapangan : | Q38: 24 | R38: 50 | S38: M-4-0 | T38: 370.8
M39: =IF(N39>=350,350,IF(N39>=325,325,IF(N39>=300,300,IF(N39>=275,275,IF(N39>=250,250,IF(N39>=225,225,IF(N39>=200,200,IF(N39>=175,175,IF(N39>=150,150,IF(N39>=125,125,IF(N39>=100,100,IF(N39>=75,75,50)))))))))))) -> 50 | N39: =L37 -> 61.7 | O39: =IF(N39<=50,50,IF(N39<=75,75,IF(N39<=100,100,IF(N39<=125,125,IF(N39<=150,150,IF(N39<=175,175,IF(N39<=200,200,IF(N39<=225,225,IF(N39<=250,250,IF(N39<=275,275,IF(N39<=300,300,IF(N39<=325,325,350)))))))))))) -> 75 | Q39: 25 | R39: 50 | S39: M-4-0 | T39: 381.6
L40: =IF(L41>=0,ROUNDDOWN(L41,0),ROUNDUP(L41,0)) -> 0 | M40: =IF(M39=350,VLOOKUP($L40,$Q$454:$T$478,4),IF(M39=325,VLOOKUP(L40,$Q$426:$T$453,4),IF(M39=300,VLOOKUP(L40,$Q$395:$T$425,4),IF(M39=275,VLOOKUP(L40,$Q$362:$T$394,4),IF(M39=250,VLOOKUP(L40,$Q$329:$T$361,4),IF(M39=225,VLOOKUP(L40,$Q$294:$T$328,4),IF(M39=200,VLOOKUP(L40,$Q$258:$T$293,4),IF(M39=175,VLOOKUP(L40,$Q$224:$T$257,4),IF(M39=150,VLOOKUP(L40,$Q$179:$T$222,4),IF(M39=125,VLOOKUP(L40,$Q$128:$T$177,4),IF(M39=100,VLOOKUP(L40,$Q$83:$T$126,4),IF(M39=75,VLOOKUP(L40,$Q$41:$T$81,4),IF(M39=50,VLOOKUP(L40,$Q$2:$T$39,4)))))))))))))) -> 120 | N40: =IFERROR((N39-M39)/(O39-M39)*(O40-M40)+M40,"") -> 113.2608 | O40: =IF(O39=350,VLOOKUP($L40,$Q$454:$T$478,4),IF(O39=325,VLOOKUP($L40,$Q$426:$T$453,4),IF(O39=300,VLOOKUP($L40,$Q$395:$T$425,4),IF(O39=275,VLOOKUP($L40,$Q$362:$T$394,4),IF(O39=250,VLOOKUP($L40,$Q$329:$T$361,4),IF(O39=225,VLOOKUP($L40,$Q$294:$T$328,4),IF(O39=200,VLOOKUP($L40,$Q$258:$T$293,4),IF(O39=175,VLOOKUP($L40,$Q$224:$T$257,4),IF(O39=150,VLOOKUP($L40,$Q$179:$T$222,4),IF(O39=125,VLOOKUP($L40,$Q$128:$T$177,4),IF(O39=100,VLOOKUP($L40,$Q$83:$T$126,4),IF(O39=75,VLOOKUP($L40,$Q$41:$T$81,4),IF(O39=50,VLOOKUP($L40,$Q$2:$T$39,4)))))))))))))) -> 105.6
...

Sheet 7113
A1: MONTHLY GAS COMPRESSION REPORT
A2: GasJack Compressor | V2: HSPHK : | W2: ='Rekap Inv'!I2 -> 1500000
C3: Unit S/N | D3: MPI 7113 | V3: Standby rate / day : | W3: ='Rekap Inv'!I3 -> 0.25
A4: Date | B4: P Source | C4: P Suct. | D4: P Disch. | E4: Volume | F4: Perf. | G4: Curve | H4: T Disch. | I4: Speed | J4: Liquid Gain | K4: Operating Time | N4: Run | O4: Availability | P4: Operating Time (hrs) | S4: Nilai | T4: Remarks | V4: Standby berturut-turut bulan sebelumnya : | W4: 4 | X4: hari
B5: psig | C5: psig | D5: psig | E5: MSCF | F5: % | G5: MSCFD | H5: °F | I5: RPM | J5: BPD | K5: Run | L5: Standby | M5: Down | N5: % | O5: % | P5: Run | Q5: Standby | R5: Down | S5: HSPHA | U5: Curve / BA
A6: ='Rekap Inv'!$I$1 -> 46023 | F6: =IF(G6="","",IF(G6="BA",100%,E6/G6)) | G6: =IF(U6="","",IF(U6="BA","BA",U6)) | H6: 55 | I6: 1845 | N6: =IF(K6="","",K6) | O6: =IF(OR(K6="",L6="",M6=""),"",(K6+L6)/SUM(K6:M6)) | S6: =IF(R6>(24-6),0,IF((AND(P6=0,(COUNTIF(Q$6:Q6,24)+$W$4)>10)),0,IF(U6="BA",(100%*P6+$W$3*Q6)/24*$W$2,(F6*P6+$W$3*Q6)/24*$W$2))) -> #VALUE!
A7: =A6+1 -> 46024 | F7: =IF(G7="","",IF(G7="BA",100%,E7/G7)) | G7: =IF(U7="","",IF(U7="BA","BA",U7)) | N7: =IF(K7="","",K7) | O7: =IF(OR(K7="",L7="",M7=""),"",(K7+L7)/SUM(K7:M7)) | S7: =IF(R7>(24-6),0,IF((AND(P7=0,(COUNTIF(Q$6:Q7,24)+$W$4)>10)),0,IF(U7="BA",(100%*P7+$W$3*Q7)/24*$W$2,(F7*P7+$W$3*Q7)/24*$W$2))) -> #VALUE!
A8: =A7+1 -> 46025 | F8: =IF(G8="","",IF(G8="BA",100%,E8/G8)) | G8: =IF(U8="","",IF(U8="BA","BA",U8)) | N8: =IF(K8="","",K8) | O8: =IF(OR(K8="",L8="",M8=""),"",(K8+L8)/SUM(K8:M8)) | S8: =IF(R8>(24-6),0,IF((AND(P8=0,(COUNTIF(Q$6:Q8,24)+$W$4)>10)),0,IF(U8="BA",(100%*P8+$W$3*Q8)/24*$W$2,(F8*P8+$W$3*Q8)/24*$W$2))) -> #VALUE!
A9: =A8+1 -> 46026 | F9: =IF(G9="","",IF(G9="BA",100%,E9/G9)) | G9: =IF(U9="","",IF(U9="BA","BA",U9)) | N9: =IF(K9="","",K9) | O9: =IF(OR(K9="",L9="",M9=""),"",(K9+L9)/SUM(K9:M9)) | S9: =IF(R9>(24-6),0,IF((AND(P9=0,(COUNTIF(Q$6:Q9,24)+$W$4)>10)),0,IF(U9="BA",(100%*P9+$W$3*Q9)/24*$W$2,(F9*P9+$W$3*Q9)/24*$W$2))) -> #VALUE!
A10: =A9+1 -> 46027 | F10: =IF(G10="","",IF(G10="BA",100%,E10/G10)) | G10: =IF(U10="","",IF(U10="BA","BA",U10)) | N10: =IF(K10="","",K10) | O10: =IF(OR(K10="",L10="",M10=""),"",(K10+L10)/SUM(K10:M10)) | S10: =IF(R10>(24-6),0,IF((AND(P10=0,(COUNTIF(Q$6:Q10,24)+$W$4)>10)),0,IF(U10="BA",(100%*P10+$W$3*Q10)/24*$W$2,(F10*P10+$W$3*Q10)/24*$W$2))) -> #VALUE!
A11: =A10+1 -> 46028 | F11: =IF(G11="","",IF(G11="BA",100%,E11/G11)) | G11: =IF(U11="","",IF(U11="BA","BA",U11)) | N11: =IF(K11="","",K11) | O11: =IF(OR(K11="",L11="",M11=""),"",(K11+L11)/SUM(K11:M11)) | S11: =IF(R11>(24-6),0,IF((AND(P11=0,(COUNTIF(Q$6:Q11,24)+$W$4)>10)),0,IF(U11="BA",(100%*P11+$W$3*Q11)/24*$W$2,(F11*P11+$W$3*Q11)/24*$W$2))) -> #VALUE!
A12: =A11+1 -> 46029 | F12: =IF(G12="","",IF(G12="BA",100%,E12/G12)) | G12: =IF(U12="","",IF(U12="BA","BA",U12)) | N12: =IF(K12="","",K12) | O12: =IF(OR(K12="",L12="",M12=""),"",(K12+L12)/SUM(K12:M12)) | S12: =IF(R12>(24-6),0,IF((AND(P12=0,(COUNTIF(Q$6:Q12,24)+$W$4)>10)),0,IF(U12="BA",(100%*P12+$W$3*Q12)/24*$W$2,(F12*P12+$W$3*Q12)/24*$W$2))) -> #VALUE!
A13: =A12+1 -> 46030 | F13: =IF(G13="","",IF(G13="BA",100%,E13/G13)) | G13: =IF(U13="","",IF(U13="BA","BA",U13)) | N13: =IF(K13="","",K13) | O13: =IF(OR(K13="",L13="",M13=""),"",(K13+L13)/SUM(K13:M13)) | S13: =IF(R13>(24-6),0,IF((AND(P13=0,(COUNTIF(Q$6:Q13,24)+$W$4)>10)),0,IF(U13="BA",(100%*P13+$W$3*Q13)/24*$W$2,(F13*P13+$W$3*Q13)/24*$W$2))) -> #VALUE!
A14: =A13+1 -> 46031 | F14: =IF(G14="","",IF(G14="BA",100%,E14/G14)) | G14: =IF(U14="","",IF(U14="BA","BA",U14)) | N14: =IF(K14="","",K14) | O14: =IF(OR(K14="",L14="",M14=""),"",(K14+L14)/SUM(K14:M14)) | S14: =IF(R14>(24-6),0,IF((AND(P14=0,(COUNTIF(Q$6:Q14,24)+$W$4)>10)),0,IF(U14="BA",(100%*P14+$W$3*Q14)/24*$W$2,(F14*P14+$W$3*Q14)/24*$W$2))) -> #VALUE!
A15: =A14+1 -> 46032 | F15: =IF(G15="","",IF(G15="BA",100%,E15/G15)) | G15: =IF(U15="","",IF(U15="BA","BA",U15)) | N15: =IF(K15="","",K15) | O15: =IF(OR(K15="",L15="",M15=""),"",(K15+L15)/SUM(K15:M15)) | S15: =IF(R15>(24-6),0,IF((AND(P15=0,(COUNTIF(Q$6:Q15,24)+$W$4)>10)),0,IF(U15="BA",(100%*P15+$W$3*Q15)/24*$W$2,(F15*P15+$W$3*Q15)/24*$W$2))) -> #VALUE!
A16: =A15+1 -> 46033 | F16: =IF(G16="","",IF(G16="BA",100%,E16/G16)) | G16: =IF(U16="","",IF(U16="BA","BA",U16)) | N16: =IF(K16="","",K16) | O16: =IF(OR(K16="",L16="",M16=""),"",(K16+L16)/SUM(K16:M16)) | S16: =IF(R16>(24-6),0,IF((AND(P16=0,(COUNTIF(Q$6:Q16,24)+$W$4)>10)),0,IF(U16="BA",(100%*P16+$W$3*Q16)/24*$W$2,(F16*P16+$W$3*Q16)/24*$W$2))) -> #VALUE!
A17: =A16+1 -> 46034 | F17: =IF(G17="","",IF(G17="BA",100%,E17/G17)) | G17: =IF(U17="","",IF(U17="BA","BA",U17)) | H17: 47.2 | I17: 1811 | N17: =IF(K17="","",K17) | O17: =IF(OR(K17="",L17="",M17=""),"",(K17+L17)/SUM(K17:M17)) | S17: =IF(R17>(24-6),0,IF((AND(P17=0,(COUNTIF(Q$6:Q17,24)+$W$4)>10)),0,IF(U17="BA",(100%*P17+$W$3*Q17)/24*$W$2,(F17*P17+$W$3*Q17)/24*$W$2))) -> #VALUE!
A18: =A17+1 -> 46035 | F18: =IF(G18="","",IF(G18="BA",100%,E18/G18)) | G18: =IF(U18="","",IF(U18="BA","BA",U18)) | H18: 50.6 | I18: 1828 | N18: =IF(K18="","",K18) | O18: =IF(OR(K18="",L18="",M18=""),"",(K18+L18)/SUM(K18:M18)) | S18: =IF(R18>(24-6),0,IF((AND(P18=0,(COUNTIF(Q$6:Q18,24)+$W$4)>10)),0,IF(U18="BA",(100%*P18+$W$3*Q18)/24*$W$2,(F18*P18+$W$3*Q18)/24*$W$2))) -> #VALUE!
A19: =A18+1 -> 46036 | F19: =IF(G19="","",IF(G19="BA",100%,E19/G19)) | G19: =IF(U19="","",IF(U19="BA","BA",U19)) | H19: 52 | I19: 1849 | N19: =IF(K19="","",K19) | O19: =IF(OR(K19="",L19="",M19=""),"",(K19+L19)/SUM(K19:M19)) | S19: =IF(R19>(24-6),0,IF((AND(P19=0,(COUNTIF(Q$6:Q19,24)+$W$4)>10)),0,IF(U19="BA",(100%*P19+$W$3*Q19)/24*$W$2,(F19*P19+$W$3*Q19)/24*$W$2))) -> #VALUE!
A20: =A19+1 -> 46037 | F20: =IF(G20="","",IF(G20="BA",100%,E20/G20)) | G20: =IF(U20="","",IF(U20="BA","BA",U20)) | H20: 51.5 | I20: 1844 | N20: =IF(K20="","",K20) | O20: =IF(OR(K20="",L20="",M20=""),"",(K20+L20)/SUM(K20:M20)) | S20: =IF(R20>(24-6),0,IF((AND(P20=0,(COUNTIF(Q$6:Q20,24)+$W$4)>10)),0,IF(U20="BA",(100%*P20+$W$3*Q20)/24*$W$2,(F20*P20+$W$3*Q20)/24*$W$2))) -> #VALUE!
A21: =A20+1 -> 46038 | F21: =IF(G21="","",IF(G21="BA",100%,E21/G21)) | G21: =IF(U21="","",IF(U21="BA","BA",U21)) | H21: 51.7 | I21: 1834 | N21: =IF(K21="","",K21) | O21: =IF(OR(K21="",L21="",M21=""),"",(K21+L21)/SUM(K21:M21)) | S21: =IF(R21>(24-6),0,IF((AND(P21=0,(COUNTIF(Q$6:Q21,24)+$W$4)>10)),0,IF(U21="BA",(100%*P21+$W$3*Q21)/24*$W$2,(F21*P21+$W$3*Q21)/24*$W$2))) -> #VALUE!
A22: =A21+1 -> 46039 | F22: =IF(G22="","",IF(G22="BA",100%,E22/G22)) | G22: =IF(U22="","",IF(U22="BA","BA",U22)) | H22: 50.4 | I22: 1837 | N22: =IF(K22="","",K22) | O22: =IF(OR(K22="",L22="",M22=""),"",(K22+L22)/SUM(K22:M22)) | S22: =IF(R22>(24-6),0,IF((AND(P22=0,(COUNTIF(Q$6:Q22,24)+$W$4)>10)),0,IF(U22="BA",(100%*P22+$W$3*Q22)/24*$W$2,(F22*P22+$W$3*Q22)/24*$W$2))) -> #VALUE!
A23: =A22+1 -> 46040 | F23: =IF(G23="","",IF(G23="BA",100%,E23/G23)) | G23: =IF(U23="","",IF(U23="BA","BA",U23)) | H23: 51.5 | I23: 1845 | N23: =IF(K23="","",K23) | O23: =IF(OR(K23="",L23="",M23=""),"",(K23+L23)/SUM(K23:M23)) | S23: 1262500
A24: =A23+1 -> 46041 | F24: =IF(G24="","",IF(G24="BA",100%,E24/G24)) | G24: =IF(U24="","",IF(U24="BA","BA",U24)) | H24: 50.2 | I24: 1855 | N24: =IF(K24="","",K24) | O24: =IF(OR(K24="",L24="",M24=""),"",(K24+L24)/SUM(K24:M24)) | S24: 1262500
A25: =A24+1 -> 46042 | F25: =IF(G25="","",IF(G25="BA",100%,E25/G25)) | G25: =IF(U25="","",IF(U25="BA","BA",U25)) | H25: 52.3 | I25: 1852 | N25: =IF(K25="","",K25) | O25: =IF(OR(K25="",L25="",M25=""),"",(K25+L25)/SUM(K25:M25)) | S25: 1262500
A26: =A25+1 -> 46043 | F26: =IF(G26="","",IF(G26="BA",100%,E26/G26)) | G26: =IF(U26="","",IF(U26="BA","BA",U26)) | H26: 53.3 | I26: 1874 | N26: =IF(K26="","",K26) | O26: =IF(OR(K26="",L26="",M26=""),"",(K26+L26)/SUM(K26:M26)) | S26: 1262500
A27: =A26+1 -> 46044 | F27: =IF(G27="","",IF(G27="BA",100%,E27/G27)) | G27: =IF(U27="","",IF(U27="BA","BA",U27)) | H27: 52 | I27: 1866 | N27: =IF(K27="","",K27) | O27: =IF(OR(K27="",L27="",M27=""),"",(K27+L27)/SUM(K27:M27)) | S27: 1262500
A28: =A27+1 -> 46045 | F28: =IF(G28="","",IF(G28="BA",100%,E28/G28)) | G28: =IF(U28="","",IF(U28="BA","BA",U28)) | H28: 50.6 | I28: 1868 | N28: =IF(K28="","",K28) | O28: =IF(OR(K28="",L28="",M28=""),"",(K28+L28)/SUM(K28:M28)) | S28: 1262500
A29: =A28+1 -> 46046 | F29: =IF(G29="","",IF(G29="BA",100%,E29/G29)) | G29: =IF(U29="","",IF(U29="BA","BA",U29)) | H29: 52.1 | I29: 1867 | N29: =IF(K29="","",K29) | O29: =IF(OR(K29="",L29="",M29=""),"",(K29+L29)/SUM(K29:M29)) | S29: 1262500
A30: =A29+1 -> 46047 | F30: =IF(G30="","",IF(G30="BA",100%,E30/G30)) | G30: =IF(U30="","",IF(U30="BA","BA",U30)) | H30: 53.1 | I30: 1869 | N30: =IF(K30="","",K30) | O30: =IF(OR(K30="",L30="",M30=""),"",(K30+L30)/SUM(K30:M30)) | S30: 1262500
A31: =A30+1 -> 46048 | F31: =IF(G31="","",IF(G31="BA",100%,E31/G31)) | G31: =IF(U31="","",IF(U31="BA","BA",U31)) | H31: 53.5 | I31: 1870 | N31: =IF(K31="","",K31) | O31: =IF(OR(K31="",L31="",M31=""),"",(K31+L31)/SUM(K31:M31)) | S31: 1262500
A32: =A31+1 -> 46049 | F32: =IF(G32="","",IF(G32="BA",100%,E32/G32)) | G32: =IF(U32="","",IF(U32="BA","BA",U32)) | H32: 54.6 | I32: 1866 | N32: =IF(K32="","",K32) | O32: =IF(OR(K32="",L32="",M32=""),"",(K32+L32)/SUM(K32:M32)) | S32: 1262500
A33: =A32+1 -> 46050 | F33: =IF(G33="","",IF(G33="BA",100%,E33/G33)) | G33: =IF(U33="","",IF(U33="BA","BA",U33)) | H33: 53.3 | I33: 1871 | N33: =IF(K33="","",K33) | O33: =IF(OR(K33="",L33="",M33=""),"",(K33+L33)/SUM(K33:M33)) | S33: 0
A34: =A33+1 -> 46051 | F34: =IF(G34="","",IF(G34="BA",100%,E34/G34)) | G34: =IF(U34="","",IF(U34="BA","BA",U34)) | H34: 54.2 | I34: 1843 | N34: =IF(K34="","",K34) | O34: =IF(OR(K34="",L34="",M34=""),"",(K34+L34)/SUM(K34:M34)) | S34: 0
A35: =A34+1 -> 46052 | F35: =IF(G35="","",IF(G35="BA",100%,E35/G35)) | G35: =IF(U35="","",IF(U35="BA","BA",U35)) | H35: 51.7 | I35: 1850 | N35: =IF(K35="","",K35) | O35: =IF(OR(K35="",L35="",M35=""),"",(K35+L35)/SUM(K35:M35)) | S35: 0
A36: =A35+1 -> 46053 | F36: =IF(G36="","",IF(G36="BA",100%,E36/G36)) | G36: =IF(U36="","",IF(U36="BA","BA",U36)) | N36: =IF(K36="","",K36) | O36: =IF(OR(K36="",L36="",M36=""),"",(K36+L36)/SUM(K36:M36)) | S36: 0
A37: TOTAL | E37: =IF(COUNT(E6:E36)=0,"",SUM(E6:E36)) | J37: =IF(COUNT(J6:J36)=0,"",SUM(J6:J36)) | K37: =IF(COUNT(K6:K36)=0,"",SUM(K6:K36)) | L37: =IF(COUNT(L6:L36)=0,"",SUM(L6:L36)) | M37: =IF(COUNT(M6:M36)=0,"",SUM(M6:M36)) | P37: =IF(COUNT(P6:P36)=0,"",SUM(P6:P36)) | Q37: =IF(COUNT(Q6:Q36)=0,"",SUM(Q6:Q36)) | R37: =IF(COUNT(R6:R36)=0,"",SUM(R6:R36)) | S37: =SUM(S6:S36) -> #VALUE!

Sheet 7116
A1: MONTHLY GAS COMPRESSION REPORT
A2: GasJack Compressor | V2: HSPHK : | W2: ='Rekap Inv'!I2 -> 1500000
C3: Unit S/N | D3: {{unit_sn}} | V3: Standby rate / day : | W3: ='Rekap Inv'!I3 -> 0.25
A4: Date | B4: P Source | C4: P Suct. | D4: P Disch. | E4: Volume | F4: Perf. | G4: Curve | H4: T Disch. | I4: Speed | J4: Liquid Gain | K4: Operating Time | N4: Run | O4: Availability | P4: Operating Time (hrs) | S4: Nilai | T4: Remarks | V4: Standby berturut-turut bulan sebelumnya : | W4: 0 | X4: hari
B5: psig | C5: {{suction_press_unit}} | D5: {{disharge_press_unit}} | E5: MSCF | F5: % | G5: MSCFD | H5: °F | I5: RPM | J5: BPD | K5: Run | L5: Standby | M5: Down | N5: % | O5: % | P5: Run | Q5: Standby | R5: Down | S5: HSPHA | U5: Curve / BA
A6: {{date}} | C6: {{suction_press}} | D6: {{discharge_press}} | E6: {{flowrate}} | F6: =IF(G6="","",IF(G6="BA",100%,E6/G6)) -> 1 | G6: =IF(U6="","",IF(U6="BA","BA",U6)) -> BA | H6: 55 | I6: 1845 | K6: {{run}} | L6: {{stby}} | M6: {{down}} | N6: 1 | O6: =IF(OR(K6="",L6="",M6=""),"",(K6+L6)/SUM(K6:M6)) -> #VALUE! | P6: =IF(K6="","",K6*24) -> #VALUE! | Q6: =IF(L6="","",L6*24) -> #VALUE! | R6: =IF(M6="","",M6*24) -> #VALUE! | S6: =IF(R6>(24-6),0,IF((AND(P6=0,(COUNTIF(Q$6:Q6,24)+$W$4)>10)),0,IF(U6="BA",(100%*P6+$W$3*Q6)/24*$W$2,(F6*P6+$W$3*Q6)/24*$W$2))) -> #VALUE! | T6: {{remarks}} | U6: BA
F7: =IF(G7="","",IF(G7="BA",100%,E7/G7)) -> 1 | G7: =IF(U7="","",IF(U7="BA","BA",U7)) -> BA | O7: =IF(OR(K7="",L7="",M7=""),"",(K7+L7)/SUM(K7:M7)) | P7: =IF(K7="","",K7*24) | Q7: =IF(L7="","",L7*24) | R7: =IF(M7="","",M7*24) | S7: =IF(R7>(24-6),0,IF((AND(P7=0,(COUNTIF(Q$6:Q7,24)+$W$4)>10)),0,IF(U7="BA",(100%*P7+$W$3*Q7)/24*$W$2,(F7*P7+$W$3*Q7)/24*$W$2))) -> 0 | U7: BA
F8: =IF(G8="","",IF(G8="BA",100%,E8/G8)) -> 1 | G8: =IF(U8="","",IF(U8="BA","BA",U8)) -> BA | O8: =IF(OR(K8="",L8="",M8=""),"",(K8+L8)/SUM(K8:M8)) | P8: =IF(K8="","",K8*24) | Q8: =IF(L8="","",L8*24) | R8: =IF(M8="","",M8*24) | S8: =IF(R8>(24-6),0,IF((AND(P8=0,(COUNTIF(Q$6:Q8,24)+$W$4)>10)),0,IF(U8="BA",(100%*P8+$W$3*Q8)/24*$W$2,(F8*P8+$W$3*Q8)/24*$W$2))) -> 0 | U8: BA
F9: =IF(G9="","",IF(G9="BA",100%,E9/G9)) -> 1 | G9: =IF(U9="","",IF(U9="BA","BA",U9)) -> BA | O9: =IF(OR(K9="",L9="",M9=""),"",(K9+L9)/SUM(K9:M9)) | P9: =IF(K9="","",K9*24) | Q9: =IF(L9="","",L9*24) | R9: =IF(M9="","",M9*24) | S9: =IF(R9>(24-6),0,IF((AND(P9=0,(COUNTIF(Q$6:Q9,24)+$W$4)>10)),0,IF(U9="BA",(100%*P9+$W$3*Q9)/24*$W$2,(F9*P9+$W$3*Q9)/24*$W$2))) -> 0 | U9: BA
F10: =IF(G10="","",IF(G10="BA",100%,E10/G10)) -> 1 | G10: =IF(U10="","",IF(U10="BA","BA",U10)) -> BA | O10: =IF(OR(K10="",L10="",M10=""),"",(K10+L10)/SUM(K10:M10)) | P10: =IF(K10="","",K10*24) | Q10: =IF(L10="","",L10*24) | R10: =IF(M10="","",M10*24) | S10: =IF(R10>(24-6),0,IF((AND(P10=0,(COUNTIF(Q$6:Q10,24)+$W$4)>10)),0,IF(U10="BA",(100%*P10+$W$3*Q10)/24*$W$2,(F10*P10+$W$3*Q10)/24*$W$2))) -> 0 | U10: BA
F11: =IF(G11="","",IF(G11="BA",100%,E11/G11)) -> 1 | G11: =IF(U11="","",IF(U11="BA","BA",U11)) -> BA | O11: =IF(OR(K11="",L11="",M11=""),"",(K11+L11)/SUM(K11:M11)) | P11: =IF(K11="","",K11*24) | Q11: =IF(L11="","",L11*24) | R11: =IF(M11="","",M11*24) | S11: =IF(R11>(24-6),0,IF((AND(P11=0,(COUNTIF(Q$6:Q11,24)+$W$4)>10)),0,IF(U11="BA",(100%*P11+$W$3*Q11)/24*$W$2,(F11*P11+$W$3*Q11)/24*$W$2))) -> 0 | U11: BA
F12: =IF(G12="","",IF(G12="BA",100%,E12/G12)) -> 1 | G12: =IF(U12="","",IF(U12="BA","BA",U12)) -> BA | O12: =IF(OR(K12="",L12="",M12=""),"",(K12+L12)/SUM(K12:M12)) | P12: =IF(K12="","",K12*24) | Q12: =IF(L12="","",L12*24) | R12: =IF(M12="","",M12*24) | S12: =IF(R12>(24-6),0,IF((AND(P12=0,(COUNTIF(Q$6:Q12,24)+$W$4)>10)),0,IF(U12="BA",(100%*P12+$W$3*Q12)/24*$W$2,(F12*P12+$W$3*Q12)/24*$W$2))) -> 0 | U12: BA
F13: =IF(G13="","",IF(G13="BA",100%,E13/G13)) -> 1 | G13: =IF(U13="","",IF(U13="BA","BA",U13)) -> BA | O13: =IF(OR(K13="",L13="",M13=""),"",(K13+L13)/SUM(K13:M13)) | P13: =IF(K13="","",K13*24) | Q13: =IF(L13="","",L13*24) | R13: =IF(M13="","",M13*24) | S13: =IF(R13>(24-6),0,IF((AND(P13=0,(COUNTIF(Q$6:Q13,24)+$W$4)>10)),0,IF(U13="BA",(100%*P13+$W$3*Q13)/24*$W$2,(F13*P13+$W$3*Q13)/24*$W$2))) -> 0 | U13: BA
F14: =IF(G14="","",IF(G14="BA",100%,E14/G14)) -> 1 | G14: =IF(U14="","",IF(U14="BA","BA",U14)) -> BA | O14: =IF(OR(K14="",L14="",M14=""),"",(K14+L14)/SUM(K14:M14)) | P14: =IF(K14="","",K14*24) | Q14: =IF(L14="","",L14*24) | R14: =IF(M14="","",M14*24) | S14: =IF(R14>(24-6),0,IF((AND(P14=0,(COUNTIF(Q$6:Q14,24)+$W$4)>10)),0,IF(U14="BA",(100%*P14+$W$3*Q14)/24*$W$2,(F14*P14+$W$3*Q14)/24*$W$2))) -> 0 | U14: BA
F15: =IF(G15="","",IF(G15="BA",100%,E15/G15)) -> 1 | G15: =IF(U15="","",IF(U15="BA","BA",U15)) -> BA | O15: =IF(OR(K15="",L15="",M15=""),"",(K15+L15)/SUM(K15:M15)) | P15: =IF(K15="","",K15*24) | Q15: =IF(L15="","",L15*24) | R15: =IF(M15="","",M15*24) | S15: =IF(R15>(24-6),0,IF((AND(P15=0,(COUNTIF(Q$6:Q15,24)+$W$4)>10)),0,IF(U15="BA",(100%*P15+$W$3*Q15)/24*$W$2,(F15*P15+$W$3*Q15)/24*$W$2))) -> 0 | U15: BA
F16: =IF(G16="","",IF(G16="BA",100%,E16/G16)) -> 1 | G16: =IF(U16="","",IF(U16="BA","BA",U16)) -> BA | O16: =IF(OR(K16="",L16="",M16=""),"",(K16+L16)/SUM(K16:M16)) | P16: =IF(K16="","",K16*24) | Q16: =IF(L16="","",L16*24) | R16: =IF(M16="","",M16*24) | S16: =IF(R16>(24-6),0,IF((AND(P16=0,(COUNTIF(Q$6:Q16,24)+$W$4)>10)),0,IF(U16="BA",(100%*P16+$W$3*Q16)/24*$W$2,(F16*P16+$W$3*Q16)/24*$W$2))) -> 0 | U16: BA
F17: =IF(G17="","",IF(G17="BA",100%,E17/G17)) -> 1 | G17: =IF(U17="","",IF(U17="BA","BA",U17)) -> BA | O17: =IF(OR(K17="",L17="",M17=""),"",(K17+L17)/SUM(K17:M17)) | P17: =IF(K17="","",K17*24) | Q17: =IF(L17="","",L17*24) | R17: =IF(M17="","",M17*24) | S17: =IF(R17>(24-6),0,IF((AND(P17=0,(COUNTIF(Q$6:Q17,24)+$W$4)>10)),0,IF(U17="BA",(100%*P17+$W$3*Q17)/24*$W$2,(F17*P17+$W$3*Q17)/24*$W$2))) -> 0 | U17: BA
F18: =IF(G18="","",IF(G18="BA",100%,E18/G18)) -> 1 | G18: =IF(U18="","",IF(U18="BA","BA",U18)) -> BA | O18: =IF(OR(K18="",L18="",M18=""),"",(K18+L18)/SUM(K18:M18)) | P18: =IF(K18="","",K18*24) | Q18: =IF(L18="","",L18*24) | R18: =IF(M18="","",M18*24) | S18: =IF(R18>(24-6),0,IF((AND(P18=0,(COUNTIF(Q$6:Q18,24)+$W$4)>10)),0,IF(U18="BA",(100%*P18+$W$3*Q18)/24*$W$2,(F18*P18+$W$3*Q18)/24*$W$2))) -> 0 | U18: BA
... F36: =IF(G36="","",IF(G36="BA",100%,E36/G36)) -> 1 | G36: =IF(U36="","",IF(U36="BA","BA",U36)) -> BA | O36: =IF(OR(K36="",L36="",M36=""),"",(K36+L36)/SUM(K36:M36)) | P36: =IF(K36="","",K36*24) | Q36: =IF(L36="","",L36*24) | R36: =IF(M36="","",M36*24) | S36: =IF(R36>(24-6),0,IF((AND(P36=0,(COUNTIF(Q$6:Q36,24)+$W$4)>10)),0,IF(U36="BA",(100%*P36+$W$3*Q36)/24*$W$2,(F36*P36+$W$3*Q36)/24*$W$2))) -> 0 | U36: BA
A37: TOTAL | E37: =IF(COUNT(E6:E36)=0,"",SUM(E6:E36)) | J37: =IF(COUNT(J6:J36)=0,"",SUM(J6:J36)) | K37: =IF(COUNT(K6:K36)=0,"",SUM(K6:K36)) | L37: =IF(COUNT(L6:L36)=0,"",SUM(L6:L36)) | M37: =IF(COUNT(M6:M36)=0,"",SUM(M6:M36)) | P37: =IF(COUNT(P6:P36)=0,"",SUM(P6:P36)) | Q37: =IF(COUNT(Q6:Q36)=0,"",SUM(Q6:Q36)) | R37: =IF(COUNT(R6:R36)=0,"",SUM(R6:R36)) | S37: =SUM(S6:S36) -> #VALUE!
